<mujoco model="URDF">
    <compiler angle="radian" />
    <asset>
        <mesh name="base" file="meshes/base.stl" scale="0.001 0.001 0.001" />
        <mesh name="coxa" file="meshes/coxa.stl" scale="0.001 0.001 0.001" />
        <mesh name="femur" file="meshes/femur.stl" scale="0.001 0.001 0.001" />
        <mesh name="tibia" file="meshes/tibia.stl" scale="0.001 0.001 0.001" />
        <mesh name="foot" file="meshes/foot.stl" scale="0.001 0.001 0.001" />
    </asset>
    <worldbody>
        <light directional="true" pos="-0.5 0.5 3" dir="0 0 -1" />

        <!--
        <geom pos="0 0 0" size="1 1 1" type="plane" rgba="1 0.83 0.61 0.5" />
        -->

        <body name="base" pos="-0.054909463967939325 0.08112311588670991 0.008962584682672215" euler="1.0408340855860816e-17 0.0 1.5707963267948966">
        <!--<body name="base" pos="-0.054909463967939325 0.08112311588670991 0.0" euler="1.0408340855860816e-17 0.0 1.5707963267948966">-->
            <freejoint/>
            <geom name="base_geom" type="mesh" mesh="base" pos="0 0 0" euler="0 0 0" />
            <inertial mass="0.23577787558266994" pos="5.2041704279304066e-20 0.0 0.005" fullinertia="6.065105499097358e-05 6.065105499097412e-05 0.00011737247872223647 0.0 5.903759120246965e-22 0.0" />
            <site name='imu' pos="0.0 0.0 0.005" size="0.0025"/>

            <!--
            <site name="base_plane_1" pos="0.0245 0.0245 0" size="0.003" rgba="0 1 0 1"/>
            <site name="base_plane_2" pos="0.0245 -0.0245 0" size="0.003" rgba="0 1 0 1"/>
            <site name="base_plane_3" pos="-0.0245 -0.0245 0" size="0.003" rgba="0 1 0 1"/>
            <site name="base_plane_4" pos="-0.0245 0.0245 0" size="0.003" rgba="0 1 0 1"/>
            -->

            <body name="leg_1_coxa" pos="-0.032399494936611664 -0.032399494936611664 -0.0029999999999999927" euler="1.5707963267948966 0.7853981633974483 -0.0">
                <joint name="base_leg_1_coxa" type="hinge" axis="-7.359808400080175e-18 -1.0 -7.359808400080175e-18" pos="0.013999589980845425 0.0030004153173277797 2.461305977216484e-07" />
                <geom name="leg_1_coxa_geom" type="mesh" mesh="coxa" pos="0 0 0" euler="0 0 0" />
                <inertial mass="0.012320734531554899" pos="0.005402213314214328 0.003646425722140868 2.6836994660080776e-20" fullinertia="3.396894349662408e-07 5.637559421977018e-07 8.049059488504037e-07 2.2585094328516103e-07 1.6622196695561594e-24 9.041216421766759e-22" />
                <body name="leg_1_femur" pos="0.0 0.01 0.008999999999999979" euler="-3.141592653589793 -5.416677968589072e-35 -3.141592653589793">
                    <joint name="leg_1_coxa_leg_1_femur" type="hinge" axis="0.0 -7.359810677565174e-18 -1.0000003094489511" pos="-2.899269141557782e-07 4.153173277822884e-07 0.006000206903608923" />
                    <geom name="leg_1_femur_geom" type="mesh" mesh="femur" pos="0 0 0" euler="0 0 0" />
                    <inertial mass="0.022539225349601982" pos="0.019999999999999955 -5.957195584254888e-20 0.0029999999999999923" fullinertia="2.477378344838158e-07 4.396427974324623e-06 4.5089304567107975e-06 4.7753444550049285e-22 1.6675961149069038e-21 8.279967148955229e-25" />
                    <body name="leg_1_tibia" pos="0.040000000000000036 0.004999999999999983 0.012000000000000033" euler="3.141592653589793 5.990253684472967e-34 1.5707963267948968">
                        <joint name="leg_1_femur_leg_1_tibia" type="hinge" axis="-3.925232361368103e-17 0.0 -1.0000003094489525" pos="0.004999584682672212 -3.357802766898806e-08 0.006000500203172275" />
                        <geom name="leg_1_tibia_geom" type="mesh" mesh="tibia" pos="0 0 0" euler="0 0 0" />
                        <inertial mass="0.014281065378017476" pos="0.005000000000000001 -0.012764398664719852 0.0030000000000000027" fullinertia="1.5898201189611037e-06 1.2601869475587917e-07 1.630152421448881e-06 1.369444446834944e-21 -5.432291851552198e-22 8.205631676526035e-22" />
                        <body name="leg_1_foot" pos="-8.881784197001253e-18 -2.220446049250313e-18 0.0" euler="1.5407439555097878e-33 -3.404814103916397e-17 -0.0">
                            <site name="leg_1_foot_site" pos="0.005 -0.035 0.003" size="0.003" rgba="0.0 0.0 1.0 1.0"/>
                            <geom name="leg_1_foot_geom" type="mesh" mesh="foot" pos="0 0 0" euler="0 0 0" />
                            <inertial mass="0.0014224078597118738" pos="0.005000000000000003 -0.03479747916365943 0.0030000000000000027" fullinertia="8.180821887655772e-09 8.881990441404547e-09 8.52836517078954e-09 -2.1573134844705383e-22 -6.622267190030097e-23 -7.940933880509065e-23" />
                        </body>
                    </body>
                </body>
            </body>
            <body name="leg_2_coxa" pos="-0.03296204818108482 0.03296204818108482 -0.0029999999999999905" euler="1.5707963267948966 -0.7853981633974483 -0.0">
                <joint name="base_leg_2_coxa" type="hinge" axis="-7.359808400080175e-18 -1.0 7.359808400080175e-18" pos="0.014795816558488634 0.003000415317327777 4.1001915457130346e-07" />
                <geom name="leg_2_coxa_geom" type="mesh" mesh="coxa" pos="0 0 0" euler="0 0 0" />
                <inertial mass="0.012320734531554899" pos="0.005402213314214328 0.003646425722140868 -2.6836994660080776e-20" fullinertia="3.3968943496623066e-07 5.637559421976882e-07 8.049059488504205e-07 2.2585094328515836e-07 3.386469569347645e-21 1.2002258361582267e-21" />
                <body name="leg_2_femur" pos="4.440892098500626e-18 0.009999999999999998 0.008999999999999985" euler="-3.141592653589793 5.416677968589089e-35 -3.141592653589793">
                    <joint name="leg_2_coxa_leg_2_femur" type="hinge" axis="1.1102230246251565e-16 -7.359810677565137e-18 -1.0000003094489505" pos="-3.1426894131231914e-07 4.153173277822884e-07 0.006000043015052069" />
                    <geom name="leg_2_femur_geom" type="mesh" mesh="femur" pos="0 0 0" euler="0 0 0" />
                    <inertial mass="0.022539225349601982" pos="0.01999999999999997 3.945200773885174e-19 0.0029999999999999905" fullinertia="2.477378344838324e-07 4.396427974324643e-06 4.508930456710802e-06 2.0849651918184504e-21 -2.63374307036884e-20 -1.1323437499974193e-21" />
                    <body name="leg_2_tibia" pos="0.039999999999999994 0.004999999999999993 0.011999999999999993" euler="-3.141592653589793 -1.1102230246251548e-16 1.5707963267948966">
                        <joint name="leg_2_femur_leg_2_tibia" type="hinge" axis="-1.2499003140340276e-17 -2.220446049250313e-16 -1.000000309448952" pos="0.004999584682672221 -9.236000512930923e-09 0.006000664091729092" />
                        <geom name="leg_2_tibia_geom" type="mesh" mesh="tibia" pos="0 0 0" euler="0 0 0" />
                        <inertial mass="0.014281065378017476" pos="0.005000000000000006 -0.012764398664719854 0.0029999999999999975" fullinertia="1.5898201189611617e-06 1.26018694755866e-07 1.630152421448865e-06 -1.991710686043742e-21 -2.363694918171814e-21 1.4306915874717167e-20" />
                        <body name="leg_2_foot" pos="2.2204460492503132e-17 -4.4408920985006264e-17 5.329070518200751e-17" euler="-3.8857805861880494e-16 -3.5529595225747607e-16 1.479114197289397e-31">
                            <site name="leg_2_foot_site" pos="0.005 -0.035 0.003" size="0.003" rgba="0.0 0.0 1.0 1.0"/>
                            <geom name="leg_2_foot_geom" type="mesh" mesh="foot" pos="0 0 0" euler="0 0 0" />
                            <inertial mass="0.0014224078597118738" pos="0.005000000000000001 -0.03479747916365934 0.002999999999999973" fullinertia="8.180821887665946e-09 8.881990441406273e-09 8.528365170791693e-09 1.1340059798977995e-22 -7.139843124002949e-22 -2.8703167255590065e-22" />
                        </body>
                    </body>
                </body>
            </body>
            <body name="leg_3_coxa" pos="0.03296204818108478 0.032962048181084835 -0.002999999999999954" euler="-1.5707963267948988 -0.7853981633974483 3.14159265358979">
                <joint name="base_leg_3_coxa" type="hinge" axis="1.3711258752665068e-15 -0.9999999999999993 1.4893062398964934e-15" pos="0.01479598044704546 0.0030004153173277606 -2.4613059776252404e-07" />
                <geom name="leg_3_coxa_geom" type="mesh" mesh="coxa" pos="0 0 0" euler="0 0 0" />
                <inertial mass="0.012320734531554899" pos="0.0054022133142143216 0.0036464257221408627 -5.4306445813034554e-18" fullinertia="3.396894349662604e-07 5.637559421977287e-07 8.049059488504237e-07 2.258509432851639e-07 -7.218503915562293e-21 3.912395089851009e-22" />
                <body name="leg_3_femur" pos="5.329070518200751e-17 0.009999999999999974 0.008999999999999894" euler="3.141592653589793 -1.6653345369377607e-16 -3.141592653589793">
                    <joint name="leg_3_coxa_leg_3_femur" type="hinge" axis="3.3306690738754696e-16 1.564270067285307e-15 -1.0000003094489502" pos="2.2894928306633746e-07 4.153173277763273e-07 0.005999992058023127" />
                    <geom name="leg_3_femur_geom" type="mesh" mesh="femur" pos="0 0 0" euler="0 0 0" />
                    <inertial mass="0.022539225349601982" pos="0.01999999999999997 -4.3681176600244935e-18 0.0029999999999999923" fullinertia="2.477378344838173e-07 4.396427974324635e-06 4.508930456710866e-06 -3.425165013786079e-21 5.288661964419037e-20 -5.0555515088679105e-22" />
                    <body name="leg_3_tibia" pos="0.040000000000000126 0.005000000000000009 0.012000000000000018" euler="3.141592653589793 -2.4560148940840263e-30 1.5707963267948961">
                        <joint name="leg_3_femur_leg_3_tibia" type="hinge" axis="1.873772050008584e-15 -2.7755575615628914e-15 -1.0000003094489514" pos="0.00499958468267229 1.5465255636485357e-07 0.006000007941976822" />
                        <geom name="leg_3_tibia_geom" type="mesh" mesh="tibia" pos="0 0 0" euler="0 0 0" />
                        <inertial mass="0.014281065378017476" pos="0.005000000000000012 -0.012764398664719822 0.0029999999999999476" fullinertia="1.5898201189611075e-06 1.2601869475599404e-07 1.6301524214488423e-06 -1.9874902486045574e-22 -7.874116966564113e-21 -9.198248411589668e-21" />
                        <body name="leg_3_foot" pos="-7.105427357601002e-17 0.0 7.549516567451065e-17" euler="-1.6653345369377607e-16 -3.552959522574772e-16 3.944304526105059e-31">
                            <site name="leg_3_foot_site" pos="0.005 -0.035 0.003" size="0.003" rgba="0.0 0.0 1.0 1.0"/>
                            <geom name="leg_3_foot_geom" type="mesh" mesh="foot" pos="0 0 0" euler="0 0 0" />
                            <inertial mass="0.0014224078597118738" pos="0.005000000000000022 -0.034797479163659266 0.0029999999999998834" fullinertia="8.18082188767272e-09 8.881990441410992e-09 8.528365170797691e-09 -9.039377905712465e-22 -9.0511718250021e-22 5.107840282514945e-21" />
                        </body>
                    </body>
                </body>
            </body>
            <body name="leg_4_coxa" pos="0.032399494936611664 -0.03239949493661168 -0.0030000000000000027" euler="-1.5707963267948963 0.7853981633974483 3.141592653589793">
                <joint name="base_leg_4_coxa" type="hinge" axis="5.3083600073573343e-17 -0.9999999999999999 -1.708405344748565e-16" pos="0.013999753869402293 0.0030004153173277875 -4.100191545578025e-07" />
                <geom name="leg_4_coxa_geom" type="mesh" mesh="coxa" pos="0 0 0" euler="0 0 0" />
                <inertial mass="0.012320734531554899" pos="0.005402213314214338 0.0036464257221408666 6.694489485212235e-18" fullinertia="3.396894349662329e-07 5.637559421977016e-07 8.049059488504101e-07 2.2585094328515995e-07 1.732650390371088e-21 3.6101016249540054e-22" />
                <body name="leg_4_femur" pos="-3.552713678800501e-17 0.009999999999999998 0.008999999999999985" euler="-3.141592653589793 -4.58388920052009e-33 -3.141592653589793">
                    <joint name="leg_4_coxa_leg_4_femur" type="hinge" axis="2.220446049250313e-16 -5.627064213833046e-17 -1.0000003094489518" pos="2.532913101465501e-07 4.153173277895209e-07 0.006000155946580012" />
                    <geom name="leg_4_femur_geom" type="mesh" mesh="femur" pos="0 0 0" euler="0 0 0" />
                    <inertial mass="0.022539225349601982" pos="0.020000000000000014 6.728537049698816e-19 0.0030000000000000096" fullinertia="2.4773783448383565e-07 4.396427974324757e-06 4.508930456710816e-06 4.943123642019833e-21 2.202285662861181e-20 -5.887852439298639e-21" />
                    <body name="leg_4_tibia" pos="0.040000000000000084 0.004999999999999983 0.012000000000000028" euler="-3.141592653589793 -5.551115123125795e-17 1.5707963267948943">
                        <joint name="leg_4_femur_leg_4_tibia" type="hinge" axis="-1.5628744103669466e-18 -1.2212453270876722e-15 -1.0000003094489496" pos="0.004999584682672181 1.303105293561133e-07 0.005999844053419971" />
                        <geom name="leg_4_tibia_geom" type="mesh" mesh="tibia" pos="0 0 0" euler="0 0 0" />
                        <inertial mass="0.014281065378017476" pos="0.004999999999999987 -0.01276439866471977 0.0029999999999999654" fullinertia="1.5898201189610393e-06 1.2601869475584603e-07 1.6301524214488374e-06 -5.3040886948909134e-21 -5.6595426641534955e-21 -2.005085804828539e-20" />
                        <body name="leg_4_foot" pos="0.0 -1.7763568394002506e-16 3.552713678800501e-17" euler="1.210947355928211e-30 -3.55295952257474e-16 -0.0">
                            <site name="leg_4_foot_site" pos="0.005 -0.035 0.003" size="0.003" rgba="0.0 0.0 1.0 1.0"/>
                            <geom name="leg_4_foot_geom" type="mesh" mesh="foot" pos="0 0 0" euler="0 0 0" />
                            <inertial mass="0.0014224078597118738" pos="0.0050000000000000235 -0.034797479163659085 0.0029999999999999237" fullinertia="8.180821887645538e-09 8.881990441400148e-09 8.528365170788553e-09 -3.910503780467494e-21 -9.027050114648893e-22 -1.8950707833589845e-21" />
                        </body>
                    </body>
                </body>
            </body>
        </body>
    </worldbody>
</mujoco>