<mujoco model="URDF">
    <compiler angle="radian" />
    <asset>
        <mesh name="base" file="meshes/base.stl" scale="0.001 0.001 0.001" />
        <mesh name="coxa" file="meshes/coxa.stl" scale="0.001 0.001 0.001" />
        <mesh name="femur" file="meshes/femur.stl" scale="0.001 0.001 0.001" />
        <mesh name="tibia" file="meshes/tibia.stl" scale="0.001 0.001 0.001" />
    </asset>w
    <worldbody>
        <light directional="true" pos="-0.5 0.5 3" dir="0 0 -1" />
        <geom pos="0 0 0" size="1 1 1" type="plane" rgba="1 0.83 0.61 0.5" />
        <body name="base" pos="-0.054909463967939325 0.08112311588670991 0.008962584682672215" euler="1.0408340855860816e-17 0.0 1.5707963267948966">
            <geom name="base_geom" type="mesh" mesh="base" pos="0 0 0" euler="0 0 0" />
            <inertial mass="0.23577787558266994" pos="5.2041704279304066e-20 0.0 0.005" fullinertia="6.065105499097358e-05 6.065105499097412e-05 0.00011737247872223647 0.0 5.903759120246965e-22 0.0" />
            <site name='imu'/>

            <!--
            <site name="base_plane_1" pos="0.0245 0.0245 0" size="0.003" rgba="0 1 0 1"/>
            <site name="base_plane_2" pos="0.0245 -0.0245 0" size="0.003" rgba="0 1 0 1"/>
            <site name="base_plane_3" pos="-0.0245 -0.0245 0" size="0.003" rgba="0 1 0 1"/>
            <site name="base_plane_4" pos="-0.0245 0.0245 0" size="0.003" rgba="0 1 0 1"/>
            -->

            <body name="leg_1_coxa" pos="-0.032399494936611664 -0.032399494936611664 -0.0029999999999999927" euler="1.5707963267948966 0.7853981633974483 -0.0">
                <joint name="base_leg_1_coxa" type="hinge" axis="-7.359808400080175e-18 -1.0 -7.359808400080175e-18" pos="0.013999589980845425 0.0030004153173277797 2.461305977216484e-07" />
                <geom name="leg_1_coxa_geom" type="mesh" mesh="coxa" pos="0 0 0" euler="0 0 0" />
                <inertial mass="0.012320734531554899" pos="0.005402213314214328 0.003646425722140868 2.6836994660080776e-20" fullinertia="3.396894349662408e-07 5.637559421977018e-07 8.049059488504037e-07 2.2585094328516103e-07 1.6622196695561594e-24 9.041216421766759e-22" />
                <body name="leg_1_femur" pos="0.0 0.01 0.008999999999999979" euler="-3.141592653589793 -5.416677968589072e-35 -3.141592653589793">
                    <joint name="leg_1_coxa_leg_1_femur" type="hinge" axis="0.0 -7.359810677565174e-18 -1.0000003094489511" pos="-2.899269141557782e-07 4.153173277822884e-07 0.006000206903608923" />
                    <geom name="leg_1_femur_geom" type="mesh" mesh="femur" pos="0 0 0" euler="0 0 0" />
                    <inertial mass="0.022539225349601982" pos="0.019999999999999955 -5.957195584254888e-20 0.0029999999999999923" fullinertia="2.477378344838158e-07 4.396427974324623e-06 4.5089304567107975e-06 4.7753444550049285e-22 1.6675961149069038e-21 8.279967148955229e-25" />
                    <body name="leg_1_tibia" pos="0.04000000000000001 0.004999999999999996 0.012000000000000007" euler="3.141592653589793 8.471498002637091e-34 1.5707963267948966">
                        <joint name="leg_1_femur_leg_1_tibia" type="hinge" axis="-7.359810677565174e-18 0.0 -1.000000309448952" pos="0.004999584682672226 -3.357802769468236e-08 0.0060005002031722435" />
                        <geom name="leg_1_tibia_geom" type="mesh" mesh="tibia" pos="0 0 0" euler="0 0 0" />
                        <inertial mass="0.01570347323772935" pos="0.005 -0.014760137212550031 0.003" fullinertia="2.225971776107233e-06 1.3490068519728355e-07 2.266651621878139e-06 -2.3020909573112153e-22 5.992421367625618e-22 -1.641126335305207e-21" />
                        <site name="leg_1_foot" pos="0.005 -0.035 0.003" size="0.003" rgba="1 0 0 1"/>
                    </body>
                </body>
            </body>
            <body name="leg_2_coxa" pos="-0.03296204818108482 0.03296204818108482 -0.0029999999999999905" euler="1.5707963267948966 -0.7853981633974483 -0.0">
                <joint name="base_leg_2_coxa" type="hinge" axis="-7.359808400080175e-18 -1.0 7.359808400080175e-18" pos="0.014795816558488634 0.003000415317327777 4.1001915457130346e-07" />
                <geom name="leg_2_coxa_geom" type="mesh" mesh="coxa" pos="0 0 0" euler="0 0 0" />
                <inertial mass="0.012320734531554899" pos="0.005402213314214328 0.003646425722140868 -2.6836994660080776e-20" fullinertia="3.3968943496623066e-07 5.637559421976882e-07 8.049059488504205e-07 2.2585094328515836e-07 3.386469569347645e-21 1.2002258361582267e-21" />
                <body name="leg_2_femur" pos="4.440892098500626e-18 0.009999999999999998 0.008999999999999985" euler="-3.141592653589793 5.416677968589089e-35 -3.141592653589793">
                    <joint name="leg_2_coxa_leg_2_femur" type="hinge" axis="1.1102230246251565e-16 -7.359810677565137e-18 -1.0000003094489505" pos="-3.1426894131231914e-07 4.153173277822884e-07 0.006000043015052069" />
                    <geom name="leg_2_femur_geom" type="mesh" mesh="femur" pos="0 0 0" euler="0 0 0" />
                    <inertial mass="0.022539225349601982" pos="0.01999999999999997 3.945200773885174e-19 0.0029999999999999905" fullinertia="2.477378344838324e-07 4.396427974324643e-06 4.508930456710802e-06 2.0849651918184504e-21 -2.63374307036884e-20 -1.1323437499974193e-21" />
                    <body name="leg_2_tibia" pos="0.03999999999999997 -0.005000000000000003 0.005999999999999961" euler="2.4651903288156586e-32 -1.110223024625155e-16 1.5707963267948966">
                        <joint name="leg_2_femur_leg_2_tibia" type="hinge" axis="2.865235718690178e-17 -4.440892098500626e-16 1.0000003094489518" pos="0.005000415317327772 -9.236000543333007e-09 -6.640917290635741e-07" />
                        <geom name="leg_2_tibia_geom" type="mesh" mesh="tibia" pos="0 0 0" euler="0 0 0" />
                        <inertial mass="0.01570347323772935" pos="0.004999999999999997 -0.01476013721255004 0.0030000000000000027" fullinertia="2.2259717761071857e-06 1.3490068519727537e-07 2.266651621878116e-06 4.1659842116393846e-21 -5.009685680014182e-21 -1.5101009262768073e-20" />
                        <site name="leg_2_foot" pos="0.005 -0.035 0.003" size="0.003" rgba="1 0 0 1"/>
                    </body>
                </body>
            </body>
            <body name="leg_3_coxa" pos="0.03296204818108478 0.032962048181084835 -0.002999999999999954" euler="-1.5707963267948988 -0.7853981633974483 3.14159265358979">
                <joint name="base_leg_3_coxa" type="hinge" axis="1.3711258752665068e-15 -0.9999999999999993 1.4893062398964934e-15" pos="0.01479598044704546 0.0030004153173277606 -2.4613059776252404e-07" />
                <geom name="leg_3_coxa_geom" type="mesh" mesh="coxa" pos="0 0 0" euler="0 0 0" />
                <inertial mass="0.012320734531554899" pos="0.0054022133142143216 0.0036464257221408627 -5.4306445813034554e-18" fullinertia="3.396894349662604e-07 5.637559421977287e-07 8.049059488504237e-07 2.258509432851639e-07 -7.218503915562293e-21 3.912395089851009e-22" />
                <body name="leg_3_femur" pos="5.329070518200751e-17 0.009999999999999974 0.008999999999999894" euler="3.141592653589793 -1.6653345369377607e-16 -3.141592653589793">
                    <joint name="leg_3_coxa_leg_3_femur" type="hinge" axis="3.3306690738754696e-16 1.564270067285307e-15 -1.0000003094489502" pos="2.2894928306633746e-07 4.153173277763273e-07 0.005999992058023127" />
                    <geom name="leg_3_femur_geom" type="mesh" mesh="femur" pos="0 0 0" euler="0 0 0" />
                    <inertial mass="0.022539225349601982" pos="0.01999999999999997 -4.3681176600244935e-18 0.0029999999999999923" fullinertia="2.477378344838173e-07 4.396427974324635e-06 4.508930456710866e-06 -3.425165013786079e-21 5.288661964419037e-20 -5.0555515088679105e-22" />
                    <body name="leg_3_tibia" pos="0.040000000000000126 -0.005 0.006000000000000025" euler="-7.888609052210106e-31 -2.220446049250285e-16 1.5707963267948963">
                        <joint name="leg_3_femur_leg_3_tibia" type="hinge" axis="-1.5810483059698108e-15 -1.1102230246251565e-16 1.0000003094489518" pos="0.005000415317327708 1.546525563634288e-07 -7.941976842214708e-09" />
                        <geom name="leg_3_tibia_geom" type="mesh" mesh="tibia" pos="0 0 0" euler="0 0 0" />
                        <inertial mass="0.01570347323772935" pos="0.0049999999999999906 -0.014760137212550033 0.002999999999999997" fullinertia="2.2259717761072924e-06 1.3490068519734604e-07 2.266651621878072e-06 -3.0019949401304815e-21 -2.685309420364964e-22 2.6827121626319788e-20" />
                        <site name="leg_3_foot" pos="0.005 -0.035 0.003" size="0.003" rgba="1 0 0 1"/>
                    </body>
                </body>
            </body>
            <body name="leg_4_coxa" pos="0.032399494936611664 -0.03239949493661168 -0.0030000000000000027" euler="-1.5707963267948963 0.7853981633974483 3.141592653589793">
                <joint name="base_leg_4_coxa" type="hinge" axis="5.3083600073573343e-17 -0.9999999999999999 -1.708405344748565e-16" pos="0.013999753869402293 0.0030004153173277875 -4.100191545578025e-07" />
                <geom name="leg_4_coxa_geom" type="mesh" mesh="coxa" pos="0 0 0" euler="0 0 0" />
                <inertial mass="0.012320734531554899" pos="0.005402213314214338 0.0036464257221408666 6.694489485212235e-18" fullinertia="3.396894349662329e-07 5.637559421977016e-07 8.049059488504101e-07 2.2585094328515995e-07 1.732650390371088e-21 3.6101016249540054e-22" />
                <body name="leg_4_femur" pos="-3.552713678800501e-17 0.009999999999999998 0.008999999999999985" euler="-3.141592653589793 -4.58388920052009e-33 -3.141592653589793">
                    <joint name="leg_4_coxa_leg_4_femur" type="hinge" axis="2.220446049250313e-16 -5.627064213833046e-17 -1.0000003094489518" pos="2.532913101465501e-07 4.153173277895209e-07 0.006000155946580012" />
                    <geom name="leg_4_femur_geom" type="mesh" mesh="femur" pos="0 0 0" euler="0 0 0" />
                    <inertial mass="0.022539225349601982" pos="0.020000000000000014 6.728537049698816e-19 0.0030000000000000096" fullinertia="2.4773783448383565e-07 4.396427974324757e-06 4.508930456710816e-06 4.943123642019833e-21 2.202285662861181e-20 -5.887852439298639e-21" />
                    <body name="leg_4_tibia" pos="0.03999999999999994 -0.005000000000000023 0.006000000000000085" euler="-4.9303806576313194e-32 -1.6653345369377336e-16 1.5707963267948966">
                        <joint name="leg_4_femur_leg_4_tibia" type="hinge" axis="7.756318864766702e-17 -4.440892098500626e-16 1.0000003094489527" pos="0.005000415317327807 1.3031052919701292e-07 1.5594657994305143e-07" />
                        <geom name="leg_4_tibia_geom" type="mesh" mesh="tibia" pos="0 0 0" euler="0 0 0" />
                        <inertial mass="0.01570347323772935" pos="0.005 -0.014760137212550078 0.0030000000000000044" fullinertia="2.2259717761072416e-06 1.3490068519729805e-07 2.26665162187815e-06 -8.570027027071127e-22 3.944652058783027e-22 -1.547158617719183e-20" />
                        <site name="leg_4_foot" pos="0.005 -0.035 0.003" size="0.003" rgba="1 0 0 1"/>
                    </body>
                </body>
            </body>
        </body>
    </worldbody>

    <sensor>
        <gyro name="imu_ang_vel" site="imu"/>
        <velocimeter name="imu_lin_vel" site="imu"/>
        <accelerometer name="imu_lin_acc" site="imu"/>
        <framequat name="orientation" objtype="site" objname="imu"/>
    </sensor>

</mujoco>