<?xml version="1.0" encoding="utf-8"?>
<mujoco model="URDF">
  <compiler angle="radian" inertiafromgeom="true"/>
  <option timestep="0.002"/>
  <asset>
    <mesh name="base" file="meshes/base.stl"/>
    <mesh name="coxa" file="meshes/coxa.stl"/>
    <mesh name="femur" file="meshes/femur.stl"/>
    <mesh name="tibia" file="meshes/tibia.stl"/>
  </asset>
  <worldbody>
    <body name="base">
      <inertial mass="0.23577787558266994" pos="5.2041704279304066e-20 0.0 0.005" fullinertia="6.065105499097358e-05 6.065105499097412e-05 0.00011737247872223647 0.0 5.903759120246965e-22 0.0"/>
      <geom type="mesh" mesh="base.stl" scale="0.001 0.001 0.001" pos="0.0 0.0 0.0" euler="0.0 0.0 0.0"/>
      <joint name="leg_1_coxa" type="hinge" pos="-0.02249999588670991 -0.02250000396793932 -4.682672214428862e-09" euler="3.141592653589793 -0.0 -1.5707963267948966" axis="0.0 0.0 1.0"/>
      <body name="leg_1_coxa">
        <inertial mass="0.012320734531554899" pos="0.00607954930077514 0.006079557382004551 -0.0006464304048130887" fullinertia="5.722976919083223e-07 5.722976919083223e-07 5.637559421977018e-07 -2.3260825694208147e-07 1.597007335343151e-07 1.5970073353431637e-07"/>
        <geom type="mesh" mesh="coxa.stl" scale="0.001 0.001 0.001" pos="0.009899490968672344 0.009899499049901754 0.0029999953173277796" euler="-1.5707963267948966 7.359808400080176e-18 -2.356194490192345"/>
        <joint name="leg_1_femur" type="hinge" pos="0.012020810000000002 0.007778179999999999 -0.006999999999999999" euler="3.141592653589793 5.416677968589073e-35 0.0" axis="0.707107 0.707107 3.830170908335114e-35"/>
        <body name="leg_1_femur">
          <inertial mass="0.022539225349601982" pos="0.016263457279522553 -0.012020813986513414 4.682672223310646e-09" fullinertia="2.37833414559731e-06 2.3783341455973135e-06 4.396427974324623e-06 2.1305963111134955e-06 3.669670471741294e-40 1.1540754098365622e-40"/>
          <geom type="mesh" mesh="femur.stl" scale="0.001 0.001 0.001" pos="0.004242641999351258 0.00424264198077716 4.682672221090201e-09" euler="1.5707963267948966 -1.1510487151465529e-16 -0.7853981633974483"/>
          <joint name="leg_1_tibia" type="hinge" pos="0.02828427 -0.028284270000000004 0.0" euler="1.5407439555097883e-33 9.013165799496008e-34 -2.4651903288156613e-32" axis="-0.7071070000000002 -0.707107 -4.84832862692823e-33"/>
          <body name="leg_1_tibia">
            <inertial mass="0.01570347323772935" pos="0.008315675330372242 -0.012558313411601657 4.682672225531093e-09" fullinertia="1.2007761535377137e-06 1.2007761535377099e-06 2.225971776107234e-06 1.0658754683404282e-06 -8.470329472543007e-22 1.177713937147963e-38"/>
            <geom type="mesh" mesh="tibia.stl" scale="0.001 0.001 0.001" pos="-0.004242638127425431 -0.004242640640923266 0.005000004682672223" euler="-0.7853981633974483 1.5707963267948963 0"/>
          </body>
        </body>
      </body>
      <joint name="leg_2_coxa" type="hinge" pos="-0.02249999588670991 0.022499996032060682 -4.682672214428862e-09" euler="3.141592653589793 -0.0 -1.5707963267948966" axis="0.0 0.0 1.0"/>
      <body name="leg_2_coxa">
        <inertial mass="0.012320734531554899" pos="-0.006642110481126933 0.0066421106264777045 -0.0006464304048130908" fullinertia="5.722976919083291e-07 5.722976919083223e-07 5.637559421976882e-07 2.3260825694209502e-07 -1.5970073353431468e-07 1.5970073353431298e-07"/>
        <geom type="mesh" mesh="coxa.stl" scale="0.001 0.001 0.001" pos="-0.010462052149024138 0.01046205229437491 0.002999995317327777" euler="-1.5707963267948966 7.359808400080176e-18 -0.7853981633974483"/>
        <joint name="leg_2_femur" type="hinge" pos="-0.008340729999999992 0.01258337 -0.006999999999999999" euler="3.141592653589793 -5.416677968589073e-35 0.0" axis="0.707107 -0.707107 -3.830170908335114e-35"/>
        <body name="leg_2_femur">
          <inertial mass="0.022539225349601982" pos="-0.012020817085635809 -0.016263458605225125 4.682672225531093e-09" fullinertia="2.3783341455973e-06 2.3783341455973508e-06 4.396427974324643e-06 -2.1305963111134925e-06 -3.669670471741299e-40 -1.6940658945086007e-21"/>
          <geom type="mesh" mesh="femur.stl" scale="0.001 0.001 0.001" pos="0.00424263888165477 -0.004242643325053823 4.682672221090201e-09" euler="1.5707963267948966 -2.132356501823911e-16 -2.356194490192345"/>
          <joint name="leg_2_tibia" type="hinge" pos="-0.028284270000000014 -0.028284270000000004 0.0" euler="-6.162975822039155e-33 1.5152067497230174e-33 4.930380657631324e-32" axis="-0.707107 0.707107 -1.631123776889653e-32"/>
          <body name="leg_2_tibia">
            <inertial mass="0.01570347323772935" pos="-0.012558316510724001 -0.008315676656074824 4.682672227751539e-09" fullinertia="1.2007761535377107e-06 1.2007761535376828e-06 2.2259717761071883e-06 -1.0658754683404215e-06 6.776263578034403e-21 -4.235164736271502e-22"/>
            <geom type="mesh" mesh="tibia.stl" scale="0.001 0.001 0.001" pos="-3.0529263206346968e-09 -3.885396435698852e-09 -0.004999995317327773" euler="-0.7853981633974483 -1.5707963267948966 0"/>
          </body>
        </body>
      </body>
      <joint name="leg_3_coxa" type="hinge" pos="0.022500004113290083 0.022499996032060682 -4.682672214428862e-09" euler="3.141592653589793 -0.0 -1.5707963267948966" axis="0.0 0.0 1.0"/>
      <body name="leg_3_coxa">
        <inertial mass="0.012320734531554899" pos="-0.0066421104811269505 -0.006642102399897496 -0.0006464304048131175" fullinertia="5.722976919083494e-07 5.722976919083359e-07 5.637559421977289e-07 -2.3260825694208147e-07 -1.5970073353431806e-07 -1.5970073353431806e-07"/>
        <geom type="mesh" mesh="coxa.stl" scale="0.001 0.001 0.001" pos="-0.010462052149024155 -0.0104620440677947 0.0029999953173277393" euler="-1.5707963267948952 -1.3711258752665072e-15 0.7853981633974482"/>
        <joint name="leg_3_femur" type="hinge" pos="-0.01258337 -0.008340720000000008 -0.006999999999999999" euler="3.141592653589793 2.116374158186469e-30 1.9721522630525295e-31" axis="-0.707107 -0.707107 -1.6254898759704362e-30"/>
        <body name="leg_3_femur">
          <inertial mass="0.022539225349601982" pos="-0.016263458459874282 0.012020819004406373 4.682672249955999e-09" fullinertia="2.3783341455972965e-06 2.378334145597405e-06 4.396427974324643e-06 2.130596311113533e-06 6.776263578034418e-21 -6.7762635780343974e-21"/>
          <geom type="mesh" mesh="femur.stl" scale="0.001 0.001 0.001" pos="-0.004242643179702981 -0.004242636962884206 4.682672216649309e-09" euler="1.5707963267948952 -1.4935905551812441e-15 2.3561944901923453"/>
          <joint name="leg_3_tibia" type="hinge" pos="-0.028284269999999997 0.028284269999999997 0.0" euler="-4.173812085533337e-61 -2.200041170737885e-31 3.944304526105059e-31" axis="0.707107 0.707107 1.876117590738102e-30"/>
          <body name="leg_3_tibia">
            <inertial mass="0.01570347323772935" pos="-0.008315676510724028 0.012558318429494708 4.682672309908042e-09" fullinertia="1.200776153537737e-06 1.2007761535376828e-06 2.2259717761072967e-06 1.0658754683403639e-06 8.36004308829115e-36 2.8546173663446057e-36"/>
            <geom type="mesh" mesh="tibia.stl" scale="0.001 0.001 0.001" pos="-3.740045642075529e-09 4.971697045164092e-09 -0.00499999531732771" euler="-2.3561944901923453 -1.5707963267948946 0"/>
          </body>
        </body>
      </body>
      <joint name="leg_4_coxa" type="hinge" pos="0.022500004113290083 -0.02250000396793932 -4.682672214428862e-09" euler="3.141592653589793 -0.0 -1.5707963267948966" axis="0.0 0.0 1.0"/>
      <body name="leg_4_coxa">
        <inertial mass="0.012320734531554899" pos="0.0060795493007751444 -0.006079549155424377 -0.0006464304048130787" fullinertia="5.722976919083223e-07 5.72297691908319e-07 5.637559421977018e-07 2.3260825694208824e-07 1.597007335343151e-07 -1.5970073353431468e-07"/>
        <geom type="mesh" mesh="coxa.stl" scale="0.001 0.001 0.001" pos="0.009899490968672358 -0.009899490823321581 0.0029999953173277883" euler="-1.5707963267948968 -5.3083600073573306e-17 2.356194490192345"/>
        <joint name="leg_4_femur" type="hinge" pos="0.007778170000000002 -0.012020810000000015 -0.006999999999999999" euler="3.141592653589793 -2.205677087359668e-33 1.232595164407831e-32" axis="-0.707107 0.7071069999999999 -3.241300140912161e-33"/>
        <body name="leg_4_femur">
          <inertial mass="0.022539225349601982" pos="0.012020815905284064 0.0162634571341718 4.682672212208417e-09" fullinertia="2.3783341455973508e-06 2.378334145597304e-06 4.396427974324752e-06 -2.130596311113492e-06 -8.470329472543003e-22 6.776263578034402e-21"/>
          <geom type="mesh" mesh="femur.stl" scale="0.001 0.001 0.001" pos="-0.004242640062006538 0.0042426418540004816 4.68267220998797e-09" euler="1.5707963267948968 -1.7554827998830864e-16 0.7853981633974485"/>
          <joint name="leg_4_tibia" type="hinge" pos="0.02828427 0.028284270000000014 -2.220446049250313e-18" euler="6.162975822039157e-33 7.672534297059725e-33 1.2325951644078312e-32" axis="0.707107 -0.7071070000000002 -1.0367299274946627e-32"/>
          <body name="leg_4_tibia">
            <inertial mass="0.01570347323772935" pos="0.012558315330372372 0.00831567518502144 4.682672194444848e-09" fullinertia="1.200776153537737e-06 1.2007761535377086e-06 2.2259717761072425e-06 -1.065875468340425e-06 8.470329472543003e-22 1.5627408539455968e-38"/>
            <geom type="mesh" mesh="tibia.stl" scale="0.001 0.001 0.001" pos="1.8725746742109807e-09 2.41434303660526e-09 -0.004999995317327806" euler="2.356194490192345 -1.5707963267948966 0"/>
          </body>
        </body>
      </body>
    </body>
  </worldbody>
</mujoco>
