<?xml version="1.0" encoding="utf-8"?>
<mujoco model="URDF">
  <compiler angle="radian" inertiafromgeom="true"/>
  <option timestep="0.002" gravity="0 0 -9.81"/>
  <asset>
    <mesh name="base" file="meshes/base.stl"/>
    <mesh name="coxa" file="meshes/coxa.stl"/>
    <mesh name="femur" file="meshes/femur.stl"/>
    <mesh name="tibia" file="meshes/tibia.stl"/>
  </asset>
  <worldbody>
    <body name="base">
      <inertial mass="0.23577787558266994" pos="5.2041704279304066e-20 0.0 0.005" diaginertia="6.065105499097358e-05 6.065105499097412e-05 0.00011737247872223647"/>
      <geom type="mesh" mesh="base" pos="0.0 0.0 0.0" quat="1.0 0.0 0.0 0.0"/>
      <body name="leg_1_coxa_frame" pos="-0.02249999588670991 -0.02250000396793932 -4.682672214428862e-09" quat="4.329780281177467e-17 0.7071067811865476 -0.7071067811865475 -4.329780281177466e-17">
        <joint name="leg_1_coxa" type="hinge" axis="0.0 0.0 1.0" pos="0 0 0"/>
        <body name="leg_1_coxa" pos="0 0 0">
          <inertial mass="0.012320734531554899" pos="0.00607954930077514 0.006079557382004551 -0.0006464304048130887" diaginertia="5.722976919083223e-07 5.722976919083223e-07 5.637559421977018e-07"/>
          <geom type="mesh" mesh="coxa" pos="0.009899490968672344 0.009899499049901754 0.0029999953173277796" quat="0.27059805007309856 -0.2705980500730985 0.6532814824381882 -0.6532814824381883"/>
          <body name="leg_1_femur_frame" pos="0.012020810000000002 0.007778179999999999 -0.006999999999999999" quat="6.123233995736766e-17 1.0 1.658379334061149e-51 -2.7083389842945365e-35">
            <joint name="leg_1_femur" type="hinge" axis="0.707107 0.707107 3.830170908335114e-35" pos="0 0 0"/>
            <body name="leg_1_femur" pos="0 0 0">
              <inertial mass="0.022539225349601982" pos="0.016263457279522553 -0.012020813986513414 4.682672223310646e-09" diaginertia="2.37833414559731e-06 2.3783341455973135e-06 4.396427974324623e-06"/>
              <geom type="mesh" mesh="femur" pos="0.004242641999351258 0.00424264198077716 4.682672221090201e-09" quat="0.6532814824381883 0.6532814824381882 -0.2705980500730985 -0.27059805007309845"/>
              <body name="leg_1_tibia_frame" pos="0.02828427 -0.028284270000000004 0.0" quat="1.0 7.703719777548942e-34 4.506582899748004e-34 -1.2325951644078307e-32">
                <joint name="leg_1_tibia" type="hinge" axis="-0.7071070000000002 -0.707107 -4.84832862692823e-33" pos="0 0 0"/>
                <body name="leg_1_tibia" pos="0 0 0">
                  <inertial mass="0.01570347323772935" pos="0.008315675330372242 -0.012558313411601657 4.682672225531093e-09" quat="1.0 0.0 0.0 3.26310233541909e-66" diaginertia="1.2007761535377137e-06 1.2007761535377099e-06 2.225971776107234e-06"/>
                  <geom type="mesh" mesh="tibia" pos="-0.004242638127425431 -0.004242640640923266 0.005000004682672223" quat="0.6532814824381883 -0.2705980500730985 0.6532814824381882 0.27059805007309845"/>
                </body>
              </body>
            </body>
          </body>
        </body>
      </body>
      <body name="leg_2_coxa_frame" pos="-0.02249999588670991 0.022499996032060682 -4.682672214428862e-09" quat="4.329780281177467e-17 0.7071067811865476 -0.7071067811865475 -4.329780281177466e-17">
        <joint name="leg_2_coxa" type="hinge" axis="0.0 0.0 1.0" pos="0 0 0"/>
        <body name="leg_2_coxa" pos="0 0 0">
          <inertial mass="0.012320734531554899" pos="-0.006642110481126933 0.0066421106264777045 -0.0006464304048130908" diaginertia="5.722976919083291e-07 5.722976919083223e-07 5.637559421976882e-07"/>
          <geom type="mesh" mesh="coxa" pos="-0.010462052149024138 0.01046205229437491 0.002999995317327777" quat="0.6532814824381883 -0.6532814824381882 0.27059805007309845 -0.2705980500730985"/>
          <body name="leg_2_femur_frame" pos="-0.008340729999999992 0.01258337 -0.006999999999999999" quat="6.123233995736766e-17 1.0 -1.658379334061149e-51 2.7083389842945365e-35">
            <joint name="leg_2_femur" type="hinge" axis="0.707107 -0.707107 -3.830170908335114e-35" pos="0 0 0"/>
            <body name="leg_2_femur" pos="0 0 0">
              <inertial mass="0.022539225349601982" pos="-0.012020817085635809 -0.016263458605225125 4.682672225531093e-09" diaginertia="2.3783341455973e-06 2.3783341455973508e-06 4.396427974324643e-06"/>
              <geom type="mesh" mesh="femur" pos="0.00424263888165477 -0.004242643325053823 4.682672221090201e-09" quat="0.2705980500730986 0.27059805007309845 -0.6532814824381882 -0.6532814824381883"/>
              <body name="leg_2_tibia_frame" pos="-0.028284270000000014 -0.028284270000000004 0.0" quat="1.0 -3.0814879110195774e-33 7.576033748615087e-34 2.465190328815662e-32">
                <joint name="leg_2_tibia" type="hinge" axis="-0.707107 0.707107 -1.631123776889653e-32" pos="0 0 0"/>
                <body name="leg_2_tibia" pos="0 0 0">
                  <inertial mass="0.01570347323772935" pos="-0.012558316510724001 -0.008315676656074824 4.682672227751539e-09" quat="1.0 0.0 -0.0 -1.6926019455616871e-65" diaginertia="1.2007761535377107e-06 1.2007761535376828e-06 2.2259717761071883e-06"/>
                  <geom type="mesh" mesh="tibia" pos="-3.0529263206346968e-09 -3.885396435698852e-09 -0.004999995317327773" quat="0.6532814824381883 -0.2705980500730985 -0.6532814824381882 -0.27059805007309845"/>
                </body>
              </body>
            </body>
          </body>
        </body>
      </body>
      <body name="leg_3_coxa_frame" pos="0.022500004113290083 0.022499996032060682 -4.682672214428862e-09" quat="4.329780281177467e-17 0.7071067811865476 -0.7071067811865475 -4.329780281177466e-17">
        <joint name="leg_3_coxa" type="hinge" axis="0.0 0.0 1.0" pos="0 0 0"/>
        <body name="leg_3_coxa" pos="0 0 0">
          <inertial mass="0.012320734531554899" pos="-0.0066421104811269505 -0.006642102399897496 -0.0006464304048131175" diaginertia="5.722976919083494e-07 5.722976919083359e-07 5.637559421977289e-07"/>
          <geom type="mesh" mesh="coxa" pos="-0.010462052149024155 -0.0104620440677947 0.0029999953173277393" quat="0.653281482438189 -0.6532814824381875 -0.27059805007309873 0.27059805007309823"/>
          <body name="leg_3_femur_frame" pos="-0.01258337 -0.008340720000000008 -0.006999999999999999" quat="6.123233995736766e-17 1.0 9.860761315262654e-32 -1.0581870790932345e-30">
            <joint name="leg_3_femur" type="hinge" axis="-0.707107 -0.707107 -1.6254898759704362e-30" pos="0 0 0"/>
            <body name="leg_3_femur" pos="0 0 0">
              <inertial mass="0.022539225349601982" pos="-0.016263458459874282 0.012020819004406373 4.682672249955999e-09" quat="1.0 0.0 -0.0 -4.7973568987702647e-91" diaginertia="2.3783341455972965e-06 2.378334145597405e-06 4.396427974324643e-06"/>
              <geom type="mesh" mesh="femur" pos="-0.004242643179702981 -0.004242636962884206 4.682672216649309e-09" quat="0.27059805007309806 0.2705980500730987 0.6532814824381876 0.653281482438189"/>
              <body name="leg_3_tibia_frame" pos="-0.028284269999999997 0.028284269999999997 0.0" quat="1.0 -1.8699652340826956e-61 -1.1000205853689425e-31 1.9721522630525295e-31">
                <joint name="leg_3_tibia" type="hinge" axis="0.707107 0.707107 1.876117590738102e-30" pos="0 0 0"/>
                <body name="leg_3_tibia" pos="0 0 0">
                  <inertial mass="0.01570347323772935" pos="-0.008315676510724028 0.012558318429494708 4.682672309908042e-09" quat="1.0 0.0 -0.0 -2.3038468514506412e-61" diaginertia="1.200776153537737e-06 1.2007761535376828e-06 2.2259717761072967e-06"/>
                  <geom type="mesh" mesh="tibia" pos="-3.740045642075529e-09 4.971697045164092e-09 -0.00499999531732771" quat="0.2705980500730987 -0.653281482438189 -0.2705980500730981 -0.6532814824381876"/>
                </body>
              </body>
            </body>
          </body>
        </body>
      </body>
      <body name="leg_4_coxa_frame" pos="0.022500004113290083 -0.02250000396793932 -4.682672214428862e-09" quat="4.329780281177467e-17 0.7071067811865476 -0.7071067811865475 -4.329780281177466e-17">
        <joint name="leg_4_coxa" type="hinge" axis="0.0 0.0 1.0" pos="0 0 0"/>
        <body name="leg_4_coxa" pos="0 0 0">
          <inertial mass="0.012320734531554899" pos="0.0060795493007751444 -0.006079549155424377 -0.0006464304048130787" diaginertia="5.722976919083223e-07 5.72297691908319e-07 5.637559421977018e-07"/>
          <geom type="mesh" mesh="coxa" pos="0.009899490968672358 -0.009899490823321581 0.0029999953173277883" quat="0.2705980500730985 -0.27059805007309856 -0.6532814824381883 0.6532814824381882"/>
          <body name="leg_4_femur_frame" pos="0.007778170000000002 -0.012020810000000015 -0.006999999999999999" quat="6.123233995736766e-17 1.0 6.162975822039155e-33 1.1028385436798344e-33">
            <joint name="leg_4_femur" type="hinge" axis="-0.707107 0.7071069999999999 -3.241300140912161e-33" pos="0 0 0"/>
            <body name="leg_4_femur" pos="0 0 0">
              <inertial mass="0.022539225349601982" pos="0.012020815905284064 0.0162634571341718 4.682672212208417e-09" quat="1.0 0.0 0.0 6.231125626933816e-98" diaginertia="2.3783341455973508e-06 2.378334145597304e-06 4.396427974324752e-06"/>
              <geom type="mesh" mesh="femur" pos="-0.004242640062006538 0.0042426418540004816 4.68267220998797e-09" quat="0.6532814824381882 0.6532814824381883 0.2705980500730985 0.27059805007309856"/>
              <body name="leg_4_tibia_frame" pos="0.02828427 0.028284270000000014 -2.220446049250313e-18" quat="1.0 3.081487911019579e-33 3.8362671485298624e-33 6.162975822039156e-33">
                <joint name="leg_4_tibia" type="hinge" axis="0.707107 -0.7071070000000002 -1.0367299274946627e-32" pos="0 0 0"/>
                <body name="leg_4_tibia" pos="0 0 0">
                  <inertial mass="0.01570347323772935" pos="0.012558315330372372 0.00831567518502144 4.682672194444848e-09" diaginertia="1.200776153537737e-06 1.2007761535377086e-06 2.2259717761072425e-06"/>
                  <geom type="mesh" mesh="tibia" pos="1.8725746742109807e-09 2.41434303660526e-09 -0.004999995317327806" quat="0.27059805007309856 0.6532814824381883 -0.2705980500730985 0.6532814824381882"/>
                </body>
              </body>
            </body>
          </body>
        </body>
      </body>
    </body>
  </worldbody>
</mujoco>
